<mujoco model="abb-gofa">

	
	<compiler meshdir="mesh" inertiafromgeom="true"/>

	<asset>
		<mesh name="link0" file="CRB15000_5kg-950_OmniCore_rev00_LINK0_CAD.STL" />
		<mesh name="link1" file="CRB15000_5kg-950_OmniCore_rev00_LINK1_CAD.STL" />
		<mesh name="link2" file="CRB15000_5kg-950_OmniCore_rev00_LINK2_CAD.stl" />
		<mesh name="link3" file="CRB15000_5kg-950_OmniCore_rev00_LINK3_CAD.stl" />
		<mesh name="link4" file="CRB15000_5kg-950_OmniCore_rev00_LINK4_CAD.stl" />
		<mesh name="link5" file="CRB15000_5kg-950_OmniCore_rev00_LINK5_CAD.stl" />
		<mesh name="link6" file="CRB15000_5kg-950_OmniCore_rev00_LINK6_CAD.stl" />
		<mesh name="gripper_body" file="gripper_body.stl" />
		<mesh name="finger1" file="finger1.stl" />
		<mesh name="finger2" file="finger2.stl" />

		<!-- Add checkerboard texture and material -->
		<texture name="checker_tex" type="2d" builtin="checker" width="512" height="512" />
		<material name="checker_mat" texture="checker_tex" texrepeat="8 8" rgba="1 1 1 1"/>
	</asset>


	<worldbody>
		<frame name="robot_offset" pos="-0.125 -0.21 0">
			<body name="robot">
				<body name="link0">
					<geom type="mesh" mesh="link0" rgba ="0.5 0.5 0.5 1" gap="0.01" mass="3.50083457958494"/>

					<body name="link1">
						<joint name="joint1" type="hinge" axis="0 0 1" range="0 360" limited="true" pos="0.125 0.21 0"/>
						<geom type="mesh" mesh="link1" rgba ="0.5 0.5 0.5 1" gap="0.01" mass="2.76743491139404"/>

						<body name="link2">
							<joint name="joint2" type="hinge" axis="0 1 0" range="-90 90" limited="true" pos="0.125 0.21 0.265"/>
							<geom type="mesh" mesh="link2" rgba ="0.5 0.5 0.5 1" gap="0.01" mass="4.28904168670464"/>

							<body name="link3">
								<joint name="joint3" type="hinge" axis="0 1 0" range="-90 90" limited="true" pos="0.125 0.21 0.71"/>
								<geom type="mesh" mesh="link3" rgba ="0.5 0.5 0.5 1" gap="0.01" mass="3.38333107992875"/>

								<body name="link4">
									<joint name="joint4" type="hinge" axis="1 0 0" range="-90 90" limited="true" pos="0.125 0.205 0.8185"/>
									<geom type="mesh" mesh="link4" rgba ="1 1 1 1" gap="0.01" mass="2.77857535641324"/>

									<body name="link5">
										<joint name="joint5" type="hinge" axis="0 1 0" range="-90 90" limited="true" pos="0.5959 0.205 0.8183"/>
										<geom type="mesh" mesh="link5" rgba ="1 1 1 1" gap="0.01" mass="3.01105814739001"/>

										<body name="link6">
											<joint name="joint6" type="hinge" axis="1 0 0" range="-360 360" limited="true" pos="0.125 0.208 0.899"/>
											<geom type="mesh" mesh="link6" mass="0.146500988015653"/>

											<body name="gripper">
												<geom type="mesh" mesh="gripper_body" rgba="0.1 0.1 1 1" mass="0.4"/>
												<site  name="ee_site" pos="0.86 0.208 0.899" size="0.01" rgba="0 1 0 1"/>
												<body>
													<joint name="joint_finger1" type="slide" axis="0 1 0" range="-0.006 0.006" limited="true" pos="0.125 0.21 0"/>
													<geom type="mesh" mesh="finger1" rgba="1 1 1 1" friction="1 1 1"/>
												</body>


												<body>
													<joint name="joint_finger2" type="slide" axis="0 1 0" range="-0.006 0.006" limited="true" pos="0.125 0.21 0"/>
													<geom type="mesh" mesh="finger2" rgba="1 1 1 1" friction="1 1 1"/>
												</body>

											</body>
										</body>
									</body>
								</body>
							</body>
						</body>
					</body>
				</body>

			</body>
		</frame>
	</worldbody>

	<actuator>
		<position name="joint1_act" joint="joint1" ctrlrange="0 6.28" kp="1000" dampratio="1.2"/>
		<position name="joint2_act" joint="joint2" ctrlrange="-3.14 3.14" kp="1000" dampratio="1"/>
		<position name="joint3_act" joint="joint3" ctrlrange="-3.14 3.14" kp="1000" dampratio="1"/>
		<position name="joint4_act" joint="joint4" ctrlrange="-3.14 3.14" kp="1000" dampratio="1"/>
		<position name="joint5_act" joint="joint5" ctrlrange="-3.14 3.14" kp="1000" dampratio="1"/>
		<position name="joint6_act" joint="joint6" ctrlrange="-3.14 3.14" kp="50" dampratio="1"/>
		<position name="finger1_act" joint="joint_finger1" ctrlrange="-0.006 0.006" kp="50" dampratio="1"/>
		<position name="finger2_act" joint="joint_finger2" ctrlrange="-0.006 0.006" kp="50" dampratio="1"/>
	</actuator>

	<contact>
		<exclude body1="link0" body2="link1"/>
		<exclude body1="link1" body2="link2"/>		
		<exclude body1="link2" body2="link3"/>
		<exclude body1="link3" body2="link4"/>
		<exclude body1="link4" body2="link5"/>
		<exclude body1="link5" body2="link6"/>
		<exclude body1="link6" body2="gripper"/>
	</contact>


</mujoco>